<?xml version="1.0"?>
<robot name="robotiq_85_gripper">

  <xacro:macro name="robotiq_85_gripper" params="prefix parent *origin">
    <joint name="${prefix}robotiq_85_base_joint" type="fixed">
      <parent link="${parent}"/>
      <child link="${prefix}robotiq_85_base_link"/>
      <origin rpy="0.0 -1.56 0" xyz="0.0 0.0 0.0"/>
      <xacro:insert_block name="origin"/>
    </joint>

    <link name="${prefix}robotiq_85_base_link">
      <visual>
        <geometry>
          <mesh filename="package://tsuzuki_sim_description/meshes/robotiq_85_gripper/visual/robotiq_85_base_link.dae"/>
        </geometry>
      </visual>
      <collision>
        <geometry>
          <mesh filename="package://tsuzuki_sim_description/meshes/robotiq_85_gripper/collision/robotiq_85_base_link.stl"/>
        </geometry>
      </collision>
      <inertial>
        <mass value="0.636951" />
        <origin xyz="0.031885 -0.000007 0.000000" />
        <inertia ixx="0.13324" ixy="-0.00005" ixz="0.00000"
                 iyx="-0.00005" iyy="0.17687" iyz="0.00000"
                 izx="0.00000" izy="0.00000" izz="0.19858" />
        <!--inertia ixx="0.013324" ixy="-0.000005" ixz="0.000000"
                 iyx="-0.000005" iyy="0.017687" iyz="0.000000"
                 izx="0.000000" izy="0.000000" izz="0.019858" /-->
        <!--inertia ixx="0.000380" ixy="0.000000" ixz="0.000000"
                 iyx="0.000000" iyy="0.001110" iyz="0.000000"
                 izx="0.000000" izy="0.000000" izz="0.001171" /-->
      </inertial>
    </link>

    <joint name="${prefix}robotiq_85_left_knuckle_joint" type="revolute">
      <parent link="${prefix}robotiq_85_base_link"/>
      <child link="${prefix}robotiq_85_left_knuckle_link"/>
      <axis xyz="0 0 1"/>
      <origin rpy="${pi} 0.0 0.0" xyz="0.05490451627 0.03060114443 0.0"/>
      <limit lower="0.0" upper="0.80285" velocity="0.5" effort="1000"/>
      <dynamics damping="0.8" friction="2.0"/>
    </joint>

    <joint name="${prefix}robotiq_85_right_knuckle_joint" type="continuous">
      <parent link="${prefix}robotiq_85_base_link"/>
      <child link="${prefix}robotiq_85_right_knuckle_link"/>
      <axis xyz="0 0 1"/>
      <origin rpy="0.0 0.0 0.0" xyz="0.05490451627 -0.03060114443 0.0"/>
      <limit lower="-3.14" upper="3.14" velocity="100.0" effort="1000"/>
      <dynamics damping="0.8" friction="2.0"/>
      <mimic joint="${prefix}robotiq_85_left_knuckle_joint"/>
    </joint>

    <link name="${prefix}robotiq_85_left_knuckle_link">
      <visual>
        <geometry>
          <mesh filename="package://tsuzuki_sim_description/meshes/robotiq_85_gripper/visual/robotiq_85_knuckle_link.dae"/>
        </geometry>
      </visual>
      <collision>
        <geometry>
          <mesh filename="package://tsuzuki_sim_description/meshes/robotiq_85_gripper/collision/robotiq_85_knuckle_link.stl"/>
        </geometry>
      </collision>
      <inertial>
        <mass value="0.018491" />
        <origin xyz="0.000926 -0.017947 0.0" />
        <inertia ixx="0.00128" ixy="0.00008" ixz="0.00000"
                 iyx="0.00008" iyy="0.00025" iyz="0.00000"
                 izx="0.00000" izy="0.00000" izz="0.00138" />
        <!--inertia ixx="0.000128" ixy="0.000008" ixz="0.000000"
                 iyx="0.000008" iyy="0.000025" iyz="0.000000"
                 izx="0.000000" izy="0.000000" izz="0.000138" /-->
        <!--inertia ixx="0.000009"  ixy="-0.000001" ixz="0.000000"
                 iyx="-0.000001" iyy="0.000001"  iyz="0.000000"
                 izx="0.000000"  izy="0.000000"  izz="0.000010" /-->
      </inertial>
    </link> 

    <link name="${prefix}robotiq_85_right_knuckle_link">
      <visual>
        <geometry>
          <mesh filename="package://tsuzuki_sim_description/meshes/robotiq_85_gripper/visual/robotiq_85_knuckle_link.dae"/>
        </geometry>
      </visual>
      <collision>
        <geometry>
          <mesh filename="package://tsuzuki_sim_description/meshes/robotiq_85_gripper/collision/robotiq_85_knuckle_link.stl"/>
        </geometry>
      </collision>
      <inertial>
        <mass value="0.018491" />
        <origin xyz="0.000926 -0.017947 0.0" />
        <inertia ixx="0.00128" ixy="0.00008" ixz="0.00000"
                 iyx="0.00008" iyy="0.00025" iyz="0.00000"
                 izx="0.00000" izy="0.00000" izz="0.00138" />
        <!--inertia ixx="0.000128" ixy="0.000008" ixz="0.000000"
                 iyx="0.000008" iyy="0.000025" iyz="0.000000"
                 izx="0.000000" izy="0.000000" izz="0.000138" /-->
        <!--inertia ixx="0.000009"  ixy="-0.000001" ixz="0.000000"
                 iyx="-0.000001" iyy="0.000001"  iyz="0.000000"
                 izx="0.000000"  izy="0.000000"  izz="0.000010" /-->
      </inertial>
    </link>

    <joint name="${prefix}robotiq_85_left_finger_joint" type="fixed">
      <parent link="${prefix}robotiq_85_left_knuckle_link"/>
      <child link="${prefix}robotiq_85_left_finger_link"/>
      <origin xyz="-0.00408552455 -0.03148604435 0.0" rpy="0 0 0" />
    </joint>

    <joint name="${prefix}robotiq_85_right_finger_joint" type="fixed">
      <parent link="${prefix}robotiq_85_right_knuckle_link"/>
      <child link="${prefix}robotiq_85_right_finger_link"/>
      <origin xyz="-0.00408552455 -0.03148604435 0.0" rpy="0 0 0" />
    </joint>

    <link name="${prefix}robotiq_85_left_finger_link">
      <visual>
        <geometry>
          <mesh filename="package://tsuzuki_sim_description/meshes/robotiq_85_gripper/visual/robotiq_85_finger_link.dae"/>
        </geometry>
      </visual>
      <collision>
        <geometry>
          <mesh filename="package://tsuzuki_sim_description/meshes/robotiq_85_gripper/collision/robotiq_85_finger_link.stl"/>
        </geometry>
      </collision>
      <inertial>
        <mass value="0.027309" />
        <origin xyz="0.021401 -0.002777 0.0" />
        <inertia ixx="0.00086" ixy="0.00030" ixz="0.00000"
                 iyx="0.00030" iyy="0.00312" iyz="0.00000"
                 izx="0.00000" izy="0.00000" izz="0.00255" />
        <!--inertia ixx="0.000086" ixy="0.000030" ixz="0.000000"
                 iyx="0.000030" iyy="0.000312" iyz="0.000000"
                 izx="0.000000" izy="0.000000" izz="0.000255" /-->
        <!--inertia ixx="0.000003"  ixy="-0.000002" ixz="0.000000"
                 iyx="-0.000002" iyy="0.000021"  iyz="0.000000"
                 izx="0.000000"  izy="0.000000"  izz="0.000020" /-->
      </inertial>
    </link> 

    <link name="${prefix}robotiq_85_right_finger_link">
      <visual>
        <geometry>
          <mesh filename="package://tsuzuki_sim_description/meshes/robotiq_85_gripper/visual/robotiq_85_finger_link.dae"/>
        </geometry>
      </visual>
      <collision>
        <geometry>
          <mesh filename="package://tsuzuki_sim_description/meshes/robotiq_85_gripper/collision/robotiq_85_finger_link.stl"/>
        </geometry>
      </collision>
      <inertial>
        <mass value="0.027309" />
        <origin xyz="0.021401 -0.002777 0.0" />
        <inertia ixx="0.00086" ixy="0.00030" ixz="0.00000"
                 iyx="0.00030" iyy="0.00312" iyz="0.00000"
                 izx="0.00000" izy="0.00000" izz="0.00255" />
        <!--inertia ixx="0.000086" ixy="0.000030" ixz="0.000000"
                 iyx="0.000030" iyy="0.000312" iyz="0.000000"
                 izx="0.000000" izy="0.000000" izz="0.000255" /-->
        <!--inertia ixx="0.000003"  ixy="-0.000002" ixz="0.000000"
                 iyx="-0.000002" iyy="0.000021"  iyz="0.000000"
                 izx="0.000000"  izy="0.000000"  izz="0.000020" /-->
      </inertial>
    </link> 

    <joint name="${prefix}robotiq_85_left_inner_knuckle_joint" type="continuous">
      <parent link="${prefix}robotiq_85_base_link"/>
      <child link="${prefix}robotiq_85_left_inner_knuckle_link"/>
      <axis xyz="0 0 1"/>
      <origin xyz="0.06142 0.0127 0" rpy="${pi} 0.0 0.0" />
      <limit lower="-3.14" upper="3.14" velocity="100.0" effort="0.1"/>
      <dynamics damping="0.8" friction="2.0"/>
      <mimic joint="${prefix}robotiq_85_left_knuckle_joint" offset="0"/>
    </joint>

    <joint name="${prefix}robotiq_85_right_inner_knuckle_joint" type="continuous">
      <parent link="${prefix}robotiq_85_base_link"/>
      <child link="${prefix}robotiq_85_right_inner_knuckle_link"/>
      <axis xyz="0 0 1"/>
      <origin xyz="0.06142 -0.0127 0" rpy="0 0 0"/>
      <limit lower="-3.14" upper="3.14" velocity="100.0" effort="0.1"/>
      <dynamics damping="0.8" friction="2.0"/>
      <mimic joint="${prefix}robotiq_85_left_knuckle_joint" offset="0"/>
    </joint>

    <link name="${prefix}robotiq_85_left_inner_knuckle_link">
      <visual>
        <geometry>
          <mesh filename="package://tsuzuki_sim_description/meshes/robotiq_85_gripper/visual/robotiq_85_inner_knuckle_link.dae"/>
        </geometry>
      </visual>
      <collision>
        <geometry>
          <mesh filename="package://tsuzuki_sim_description/meshes/robotiq_85_gripper/collision/robotiq_85_inner_knuckle_link.stl"/>
        </geometry>
      </collision>
      <inertial>
        <mass value="0.029951" />
        <origin xyz="0.021278 -0.018589 0.0" />
        <inertia ixx="0.00348" ixy="0.00184" ixz="0.00000"
                 iyx="0.00184" iyy="0.00398" iyz="0.00000"
                 izx="0.00000" izy="0.00000" izz="0.00396" />
        <!--inertia ixx="0.000348" ixy="0.000184" ixz="0.000000"
                 iyx="0.000184" iyy="0.000398" iyz="0.000000"
                 izx="0.000000" izy="0.000000" izz="0.000396" /-->
        <!--inertia ixx="0.000039" ixy="0.000000" ixz="0.000000"
                 iyx="0.000000" iyy="0.000005" iyz="0.000000"
                 izx="0.000000" izy="0.000000" izz="0.000035" /-->
      </inertial>
    </link>
    <link name="${prefix}robotiq_85_right_inner_knuckle_link">
      <visual>
        <geometry>
          <mesh filename="package://tsuzuki_sim_description/meshes/robotiq_85_gripper/visual/robotiq_85_inner_knuckle_link.dae"/>
        </geometry>
      </visual>
      <collision>
        <geometry>
          <mesh filename="package://tsuzuki_sim_description/meshes/robotiq_85_gripper/collision/robotiq_85_inner_knuckle_link.stl"/>
        </geometry>
      </collision>
      <inertial>
        <mass value="0.029951" />
        <origin xyz="0.021278 -0.018589 0.0" />
        <inertia ixx="0.00348" ixy="0.00184" ixz="0.00000"
                 iyx="0.00184" iyy="0.00398" iyz="0.00000"
                 izx="0.00000" izy="0.00000" izz="0.00396" />
        <!--inertia ixx="0.000348" ixy="0.000184" ixz="0.000000"
                 iyx="0.000184" iyy="0.000398" iyz="0.000000"
                 izx="0.000000" izy="0.000000" izz="0.000396" /-->
        <!--inertia ixx="0.000039" ixy="0.000000" ixz="0.000000"
                 iyx="0.000000" iyy="0.000005" iyz="0.000000"
                 izx="0.000000" izy="0.000000" izz="0.000035" /-->
      </inertial>
    </link>

    <joint name="${prefix}robotiq_85_left_finger_tip_joint" type="continuous">
      <parent link="${prefix}robotiq_85_left_inner_knuckle_link"/>
      <child link="${prefix}robotiq_85_left_finger_tip_link"/>
      <axis xyz="0 0 1"/>
      <origin xyz="0.04303959807 -0.03759940821 0.0" rpy="0.0 0.0 0.0"/>
      <limit lower="-3.14" upper="3.14" velocity="100.0" effort="0.1"/>
      <dynamics damping="0.8" friction="2.0"/>
      <mimic joint="${prefix}robotiq_85_left_knuckle_joint" multiplier="-1"/>
    </joint>

    <joint name="${prefix}robotiq_85_right_finger_tip_joint" type="continuous">
      <parent link="${prefix}robotiq_85_right_inner_knuckle_link"/>
      <child link="${prefix}robotiq_85_right_finger_tip_link"/>
      <axis xyz="0 0 1"/>
      <origin rpy="0.0 0.0 0.0" xyz="0.04303959807 -0.03759940821  0.0"/>
      <limit lower="-3.14" upper="3.14" velocity="100.0" effort="0.1"/>
      <dynamics damping="0.8" friction="2.0"/>
      <mimic joint="${prefix}robotiq_85_left_knuckle_joint" multiplier="-1"/>
    </joint>


    <link name="${prefix}robotiq_85_left_finger_tip_link">
      <visual>
        <geometry>
          <mesh filename="package://tsuzuki_sim_description/meshes/robotiq_85_gripper/visual/robotiq_85_finger_tip_link.dae"/>
        </geometry>
      </visual>
      <collision>
        <geometry>
          <mesh filename="package://tsuzuki_sim_description/meshes/robotiq_85_gripper/collision/robotiq_85_finger_tip_link.stl"/>
        </geometry>
      </collision>
      <inertial>
        <mass value="0.019555" />
        <origin xyz="0.014854 -0.001507 0.0" />
        <inertia ixx="0.00106"  ixy="-0.00096" ixz="0.00000"
                 iyx="-0.00096" iyy="0.00344"  iyz="0.00000"
                 izx="0.00000"  izy="0.00000"  izz="0.00381" />
        <!--inertia ixx="0.000106"  ixy="-0.000096" ixz="0.000000"
                 iyx="-0.000096" iyy="0.000344"  iyz="0.000000"
                 izx="0.000000"  izy="0.000000"  izz="0.000381" /-->
        <!--inertia ixx="0.000002" ixy="0.000000" ixz="0.000000"
                 iyx="0.000000" iyy="0.000005" iyz="0.000000"
                 izx="0.000000" izy="0.000000" izz="0.000006" /-->
      </inertial>
    </link> 

    <link name="${prefix}robotiq_85_right_finger_tip_link">
      <visual>
        <geometry>
          <mesh filename="package://tsuzuki_sim_description/meshes/robotiq_85_gripper/visual/robotiq_85_finger_tip_link.dae"/>
        </geometry>
      </visual>
      <collision>
        <geometry>
          <mesh filename="package://tsuzuki_sim_description/meshes/robotiq_85_gripper/collision/robotiq_85_finger_tip_link.stl"/>
        </geometry>
      </collision>
      <inertial>
        <mass value="0.019555" />
        <origin xyz="0.014854 -0.001507 0.0" />
        <inertia ixx="0.00106"  ixy="-0.00096" ixz="0.00000"
                 iyx="-0.00096" iyy="0.00344"  iyz="0.00000"
                 izx="0.00000"  izy="0.00000"  izz="0.00381" />
        <!--inertia ixx="0.000106"  ixy="-0.000096" ixz="0.000000"
                 iyx="-0.000096" iyy="0.000344"  iyz="0.000000"
                 izx="0.000000"  izy="0.000000"  izz="0.000381" /-->
        <!--inertia ixx="0.000002" ixy="0.000000" ixz="0.000000"
                 iyx="0.000000" iyy="0.000005" iyz="0.000000"
                 izx="0.000000" izy="0.000000" izz="0.000006" /-->
      </inertial>
    </link>

    <xacro:robotiq_85_gripper_transmission prefix="${prefix}" />

    <!-- The following are additions by nosaka and yamakawa -->
    <!-- add finger destination by yamakawa -->
    <link name="${prefix}ur5_gripper_link" />
    <joint name="${prefix}ur5_gripper_joint" type="fixed">
      <parent link="${prefix}robotiq_85_base_link" />
      <child link="${prefix}ur5_gripper_link" />
      <origin xyz="0.16 0 0" rpy="0 ${-pi/2} 0" />
    </joint>

  </xacro:macro>
</robot>
